## C++ 강좌

> 형변환 - static_cast, dynami_cast

C++엥서는 4가지 방식의 형변환이 존재함.
- `static_cast, dynamic_cast, const_cast, reinterpret_case`

<br>

`static_cast`

```cpp
#include <iostream>

using namespace std;



int main(){



 int n = 5;

 double f = static_cast<double>(n);

 cout << f << endl;



 return 0;

 

}
```

```cpp
#include <iostream>

using namespace std;



int main(){



 double f = 3.14;

 int n = static_cast<int>(f);

 cout << n << endl;



 return 0;

 

}
```

3.14가 3으로 바뀌는 것.
**하지만** string형을 int 형으로 바꾸는 등 컴파일러가 허용하지 않는 범위에서는 형변환이 안됨.
또한 static_cast는 대부분 포인터 형변환이 불가함.
- int형 포인터를 double형 포인터로 바꾸는 것이 안됨.

```cpp
#include <iostream>

using namespace std;



int main(){



 int n = 5, *p;

 double f = 3.14, *q;

 p = &n;

 q = static_cast<double*>(&n);



 return 0;

}
```
- 에러 남.

포인터 형변환이 의미있는 경우는 *클래스 상속*과 연관될 때임.

```cpp
#include <iostream>

using namespace std;



class Parent{};

class Child: public Parent{};



int main(){



 Parent parent, *p;

 Child child, *c;

 p = static_cast<Parent*>(&child);

 c = static_cast<Child*>(&parent);



 return 0;

}
```

p는 부모 클래스 자료형을 자식 클래스 자료형에 할당하는 **업 캐스팅**을 실행,
c는 반대인 **다운 캐스팅**을 실행.

- 업캐스팅의 경우 문제가 안되지만 다운 캐스팅의 경우 문제가 됨.
    - 원래 존재하지도 않는 값을 참조할 수도 있기 때문.
    - `dynamic_cast` 등장

<br>

`dynamic_cast`
- **상속 관계에 있는 클래스 포인터끼리 형변환을 허용하되, 다운 캐스팅이 나타나면 null 값을 대신 리턴하여 위험성을 알림.**
- 때문에 형 변환을 사용할 때는 먼저 결과가 null(0)이 아닌지 확인하는 습관
- 또한 이 형변환을 사용할 때는 클래스가 **다형성을** 가져야 함.
    - virtual 함수가 존재해야 한다는 뜻.

```cpp
#include <iostream>

using namespace std;



class Parent{

public:

 virtual void print(){ cout << "PARENT" << endl; }

};



class Child: public Parent{

public:

 void print(){ cout << "CHILD" << endl; }

};



int main(){



 Parent parent, *p;

 Child child, *c;



 p = dynamic_cast<Parent*>(&parent);

 if(p) p->print();

 else cout << "casting failed" << endl;



 p = dynamic_cast<Parent*>(&child);

 if(p) p->print();

 else cout << "casting failed" << endl;



 c = dynamic_cast<Child*>(&parent);

 if(c) c->print();

 else cout << "casting failed" << endl;



 c = dynamic_cast<Child*>(p);

 if(c) c->print();

 else cout << "casting failed" << endl;



 return 0;

}
```

첫 번째 경우는 부모를 부모에 넣는 것이므로 당연히 성공.

두 번째 경우는 부모 형이 자식 형을 가리키는 업캐스팅이므로 성공.

그리고, print() 함수를 부르면 가상 함수의 성질에 따라 자식의 것이 호출됨.

세 번째 경우는 단순한 다운캐스팅이므로 실패.

- 따라서 if문의 조건이 맞지 않아 캐스팅에 실패했다는 문구가 뜸.


네 번째 경우는 비록 부모 형 포인터의 값을 가져왔으나

그게 사실 자식 형 개체를 가리키는 값이었으므로 결과적으로 성공.


```
PARENT

CHILD

casting failed

CHILD

[커서]
```

---

> 형변환 - const_cast, reinterpret_cast

`const_cast`
- 원래는 const형인 값의 포인터를 const형이 아닌 포인터로 바꾸는 역할

```cpp
#include <iostream>

using namespace std;



int main(){



 const int c = 355;

 int *p = const_cast<int*>(&c);

 cout << *p << endl;



 return 0;

}
```

캐스팅 가능.

```cpp
#include <iostream>

using namespace std;



int main(){



 const int c = 355;

 int *p = const_cast<int*>(&c);

 *p = 240;

 cout << *p << endl;

 cout << c << endl;



 return 0;

}
```

```
240
355
```

결과가 매우 이상함.
*p를 통한 값의 변경을 이루어졌으나, c를 출력해보면 값은 그대로임. 주소도 같음
- const_cast의 주된 역할은 **포인터의 const 성질을 없애는 것**
- 따라서 결과값인 포인터를 사용하더라도 원래의 상수값 자체를 바꾸는 일은 일어나지 않음.
    - 일반적인 변수는 스택이나 힙 공간에 저장되고 참조되지만,
    - 상수의 경우 특수한 세그먼트에 저장이 되며, 상수에 대한 포인터나 레퍼런스가 발생할 경우 그것을 가리키는 임시값이 생성됨.
    - 그래서 저렇게 되는 것...
- c를 가리키는 포인터 p가 const의 성질을 걷어냄으로서 수정은 가능했으나,
진짜 상수인 c를 다시 참조해보려 하면 원래 값이 튀어나오는 것도 상수 매커니즘이 따로 작동하기 때문.

```cpp
#include <iostream>

using namespace std;



int main(){



 const int *c = new int(355);

 int *p = const_cast<int*>(c);

 *p = 240;

 cout << *p << endl;

 cout << *c << endl;



 return 0;

}
```

참고로 처음부터 c가 포인터였다면 결과도 둘 다 240임.

```cpp
#include <iostream>

using namespace std;



int main(){



 int n = 5;

 double f = const_cast<double>(n);



 return 0;

}
```

이런 거 에러남. 일반적인 용도로 사용이 불가능.
`const_cast`는 오로지 const 성질을 없애는 데에만 사용됨.

그렇다면 어디에 쓸모가 있느냐


```cpp
#include <iostream>

using namespace std;



int arraySum(int *arr, int size){

 int result = 0;

 for(int i=0; i<size; i++)

  result += *(arr+i);

 return result;

}



int main(){

 int *a = new int[5];

 a[0] = 1;

 a[1] = 2;

 a[2] = 4;

 a[3] = 7;

 a[4] = 11;

 const int *p = a;

 cout << "배열의 합: " << arraySum(const_cast<int*>(p), 5) << endl;



 return 0;

}
```

일반적인 포인터를 매개변수로 사용하는 함수에 const 포인터를 넣을 수 없을 때 잠시나마 const 성질을 제거해서 넣어줌.

<br>

`reinterpret_cast`
- 원래 자료형 상관없이 강제러 넣음.
- int, double 같은 기본적인 자료형 간에는 성립하지 않고
- 포인터의 자료형이 다를 때나, 포인터를 포인터가 아닌 변수에 넣을 때 사용됨.

```cpp
#include <iostream>

using namespace std;



int main(){



 int *p = new int(5);

 double *f = reinterpret_cast<double*>(p);

 cout << *f << endl;



 return 0;

}
```
- 쓰레기 값 나옴

```cpp
#include <iostream>

using namespace std;



int main(){



 int *p = new int(5);

 int address = reinterpret_cast<int>(p);

 cout << address << endl;



 return 0;

}
```

- 포인터와 포인터가 아닌 것들끼리 형변환이 됨.
- address에는 말 그대로 5의 주소가 int형에 들어감.

```cpp
#include <iostream>

using namespace std;



int main(){



 int arr[5] = {1, 2, 4, 8, 16};

 int address = reinterpret_cast<int>(arr);

 address += sizeof(int)*3;

 int *p = reinterpret_cast<int*>(address);

 cout << *p << endl;



 return 0;

}
```

- 배열 arr의 시작주소를 얻은 후 12를 더해서 arr[3]의 주소를 강제로 만들고 포인터 p에 넣음.

```
8
[커서]
```

결과는 제대로 나옴.

```cpp
#include <iostream>

using namespace std;



int main(){



 int arr[5] = {1, 2, 4, 8, 16}, i = 32;

 int address = reinterpret_cast<int>(arr);

 address += sizeof(int)*5;

 int *p = reinterpret_cast<int*>(address);

 cout << *p << endl;



 return 0;

}
```

```
-858993460
[커서]
```

배열은 일렬로 할당되는 것이 맞지만, 서로 다른 변수들끼리는 메모리상에서도 일렬로 할당되는 것이 아님.

---

> 예외 처리 - try, throw, catch

```cpp
#include <iostream>
using namespace std;

int main(){

 int students, scores;
 cout << "학생 수를 입력하세요: ";
 cin >> students;
 cout << "점수의 합을 입력하세요: ";
 cin >> scores;
 try{
  if(students == 0) throw(scores);
  cout << "평균은 " << scores/(double)students << "점입니다." << endl;
 }
 catch(int e){
  cout << "학생 수가 0명입니다!!" << endl;
  cout << "입력되었던 scores 값은 " << e << "입니다." << endl;
 }

 return 0;
}
```

- `try` : 예외 처리를 사용하겠다는 블록을 지정
- `throw` : try 안에서만 사용 가능하며, 자료형에 상관없이 어떤 값 하나를 넣어서 전달함.
    - throw 명령이 발생하게 되면 try 문의 남은 내용은 전부다 건너뜀.
- `catch` : 평소에는 실행되지 않지만 throw 연산이 실행되었을 경우 적절한 것을 골라 실행함.

try 문 바로 뒤에는 catch 문이 하나 이상 있어야 하며, catch 문은 여러 개 있어도 괜찮.

```
학생 수를 입력하세요: 0[엔터]
점수의 합을 입력하세요: 555[엔터]
학생 수가 0명입니다!!
입력되었던 scores 값은 555입니다.
[커서]
```


1) throw 문은 try 문 안에서만 가능하다.
2) try 문 다음에는 catch 문이 하나 이상 있어야 한다.

```cpp
#include <iostream>
#include <string>
#include <cctype>
using namespace std;

int main(){

 string id;
 try{
  cout << "id를 입력하세요(첫 글자는 영문자여야 합니다): ";
  cin >> id;
  if(!isalpha(id[0])) throw id;
  cout << "id: " << id << endl;
 }
 catch(string e){
  cout << "잘못된 입력입니다! (" << e << ")" << endl;
 }

 return 0;
}
```

예외 처리 구문은 중복 내용을 줄이는 데도 도움이 됨.

```cpp
#include <iostream>
using namespace std;

int main(){

 int x, y, z;
 try{
  cout << "가로 길이를 입력하세요: ";
  cin >> x;
  if(x <= 0) throw x;
  cout << "세로 길이를 입력하세요: ";
  cin >> y;
  if(y <= 0) throw y;
  cout << "높이를 입력하세요: ";
  cin >> z;
  if(z <= 0) throw z;
  cout << "부피: " << x*y*z << endl;
 }
 catch(int e){
  cout << "잘못된 입력입니다: ";
  if(e == 0) cout << "0 입력" << endl;
  else cout << "음수 입력" << endl;
 }

 return 0;
}
```

--- 

> 예외 처리 - 여러 개의 catch

```cpp
#include <iostream>

#include <string>

#include <cctype>

using namespace std;



int main(){



 string id;

 int score;

 try{

  cout << "id를 입력하세요(첫 글자는 영문자여야 합니다): ";

  cin >> id;

  if(!isalpha(id[0])) throw id;

  cout << "점수를 입력하세요(0~100점): ";

  cin >> score;

  if(score < 0 || score > 100) throw score;



  cout << id << ": " << score << "점" << endl;

 }

 catch(string e){

  cout << "잘못된 id 입력입니다! (" << e << ")" << endl;

 }

 catch(int e){

  cout << "잘못된 점수 입력입니다! (" << e << ")" << endl;

 }

 cout << "프로그램을 종료합니다." << endl;



 return 0;

}
```

catch 문으로 받는 변수는 1개만 가능함.
예외의 종류를 서로 다른 **자료형**으로 판별한다는 것.

```cpp
#include <iostream>

#include <string>

#include <cctype>

using namespace std;



int main(){



 string id;

 int score;

 try{

  cout << "id를 입력하세요(첫 글자는 영문자여야 합니다): ";

  cin >> id;

  if(!isalpha(id[0])) throw id;

  cout << "점수를 입력하세요(0~100점): ";

  cin >> score;

  if(score < 0 || score > 100) throw score;



  cout << id << ": " << score << "점" << endl;

 }

 catch(...){

  cout << "잘못된 입력입니다!" << endl;

 }

 cout << "프로그램을 종료합니다." << endl;



 return 0;

}
```

catch 문에서 아무 자료형의 예외나 다 받아서 처리하는 것도 가능.
`...`를 써주면 어떤 throw든지 발생하면 다 받을 수 있음.
- 값을 넘겨 받을 수는 없음. 단지 예외가 발생했다는 것만 알 수 있음.

```cpp
#include <iostream>

#include <string>

#include <cctype>

using namespace std;



int main(){



 string id;

 int scores, subjects;

 try{

  cout << "id를 입력하세요(첫 글자는 영문자여야 합니다): ";

  cin >> id;

  if(!isalpha(id[0])) throw id;

  cout << "총점을 입력하세요(0점 이상): ";

  cin >> scores;

  if(scores < 0) throw scores;

  cout << "과목 수를 입력하세요(1개 이상): ";

  cin >> subjects;

  if(subjects <= 0) throw '!';



  cout << id << ": 평균 " << scores/(double)subjects << "점" << endl;

 }

 catch(string e){

  cout << "잘못된 id 입력입니다! (" << e << ")" << endl;

 }

 catch(int e){

  cout << "잘못된 점수 입력입니다! (" << e << ")" << endl;

 }

 catch(...){

  cout << "그 외 잘못된 입력입니다!" << endl;

 }

 cout << "프로그램을 종료합니다." << endl;



 return 0;

}
```

`...`문은 제일 아래에 써줘야 함.

---

> 예외 처리 - 사용자 정의 클래스 throw

여러 개의 예외를 처리해야 한다면 ? -> 클래스를 만듦으로써 해결 가능

내용이 하나도 없는 기초적인 클래스
```cpp
#include <iostream>

#include <string>

#include <cctype>

using namespace std;



class InvalidId{};

class InvalidScore{};



int main(){



 string id;

 int score;

 try{

  cout << "id를 입력하세요(첫 글자는 영문자여야 합니다): ";

  cin >> id;

  if(!isalpha(id[0])) throw InvalidId();

  cout << "점수를 입력하세요(0점 이상): ";

  cin >> score;

  if(score < 0) throw InvalidScore();



  cout << id << ": " << score << "점" << endl;

 }

 catch(InvalidId e){

  cout << "잘못된 id 입력입니다!" << endl;

 }

 catch(InvalidScore e){

  cout << "잘못된 점수 입력입니다!" << endl;

 }

 catch(...){

  cout << "DEFAULT EXCEPTION" << endl;

 }

 cout << "프로그램을 종료합니다." << endl;



 return 0;

}
```

```
id를 입력하세요(첫 글자는 영문자여야 합니다): asdf[엔터]

점수를 입력하세요(0점 이상): -8100[엔터]

잘못된 점수 입력입니다!

프로그램을 종료합니다.

[커서]
```

```cpp
#include <iostream>

#include <string>

#include <cctype>

using namespace std;



class InvalidId{

public:

 InvalidId(char c):firstChar(c){}

 char getFirstChar(){ return firstChar; }

private:

 char firstChar;

};



class InvalidScore{};



int main(){



 string id;

 int score;

 try{

  cout << "id를 입력하세요(첫 글자는 영문자여야 합니다): ";

  cin >> id;

  if(!isalpha(id[0])) throw InvalidId(id[0]);

  cout << "점수를 입력하세요(0점 이상): ";

  cin >> score;

  if(score < 0) throw InvalidScore();



  cout << id << ": " << score << "점" << endl;

 }

 catch(InvalidId e){

  cout << "잘못된 id 입력입니다! (첫 글자: " << e.getFirstChar();

  cout << ")" << endl;

 }

 catch(InvalidScore e){

  cout << "잘못된 점수 입력입니다!" << endl;

 }

 catch(...){

  cout << "DEFAULT EXCEPTION" << endl;

 }

 cout << "프로그램을 종료합니다." << endl;



 return 0;

}
```

```
id를 입력하세요(첫 글자는 영문자여야 합니다): 0804[엔터]

잘못된 id 입력입니다! (첫 글자: 0)

프로그램을 종료합니다.

[커서]
```

멤버 변수를 2개 가진 클래스
0으로 나누는 예제

```cpp
#include <iostream>

using namespace std;



class DividedBy0{

public:

 DividedBy0(int p, int q):dividend(p),divisor(q){}

 int getDividend(){ return dividend; }

 int getDivisor(){ return divisor; }

private:

 int dividend, divisor;

};



int main(){



 int students, scores;

 cout << "학생 수를 입력하세요: ";

 cin >> students;

 cout << "점수의 합을 입력하세요: ";

 cin >> scores;

 try{

  if(students == 0) throw DividedBy0(scores, students);

  cout << "평균은 " << scores/(double)students << "점입니다." << endl;

 }

 catch(DividedBy0 e){

  cout << e.getDividend() << "(을)를 ";

  cout << e.getDivisor() << "(으)로 나눴습니다." << endl;

 }

 catch(...){

  cout << "DEFAULT EXCEPTION" << endl;

 }

 cout << "프로그램을 종료합니다." << endl;



 return 0;

}
```

```
학생 수를 입력하세요: 0[엔터]

점수의 합을 입력하세요: 227[엔터]

EXCEPTION: 227(을)를 0(으)로 나눴습니다.

프로그램을 종료합니다.

[커서]
```

---

> 예외 처리 - 함수 안에서의 throw

함수 안에서의 예외 처리 구문.
- 함수 안에서는 try, catch 문은 없고 경우에 따른 throw 문만 있는 경우
- 이 함수는 사용하려면 try 문으로 둘러싸고, catch 문도 달아 줘야 함.
    - 그렇지 않을 경우 예외가 발생하지 않으면 외관상 문제는 없지만, 예외가 발생하면 프로그램 자체가 강제 종료됨.

```cpp
#include <iostream>

using namespace std;



class DividedBy0{

public:

 DividedBy0(int p, int q):dividend(p),divisor(q){}

 int getDividend(){ return dividend; }

 int getDivisor(){ return divisor; }

private:

 int dividend, divisor;

};



void printAverageScore(int students, int scores){

 if(students == 0) throw DividedBy0(scores, students);

 cout << "평균은 " << scores/(double)students << "점입니다." << endl;

}



int main(){



 int students, scores;

 cout << "학생 수를 입력하세요: ";

 cin >> students;

 cout << "점수의 합을 입력하세요: ";

 cin >> scores;

 try{

  printAverageScore(students, scores);

 }

 catch(DividedBy0 e){

  cout << "EXCEPTION: " << e.getDividend() << "(을)를 ";

  cout << e.getDivisor() << "(으)로 나눴습니다." << endl;

 }



 return 0;

}
```

main()함수가 아닌 `printAverageScore()` 함수 안에서 throw 하게 됨.

```
학생 수를 입력하세요: 0[엔터]

점수의 합을 입력하세요: 174[엔터]

EXCEPTION: 174(을)를 0(으)로 나눴습니다.

[커서]
```

```cpp
#include <iostream>

using namespace std;



class DividedBy0{

public:

 DividedBy0(int p, int q):dividend(p),divisor(q){}

 int getDividend(){ return dividend; }

 int getDivisor(){ return divisor; }

private:

 int dividend, divisor;

};



class Group{

public:

 void initialize(){

  cout << "학생 수를 입력하세요: ";

  cin >> students;

  cout << "점수의 합을 입력하세요: ";

  cin >> scores;

 }

 double getAverageScore(){

  if(students == 0) throw DividedBy0(scores, students);

  return scores/(double)students;

 }

private:

 int students, scores;

};



int main(){



 const int MAX = 3;

 Group g[MAX];

 for(int i=0; i<MAX; i++){

  cout << "<< GROUP " << i+1 << " INPUT >>" << endl;

  g[i].initialize();

 }



 cout << endl << "<< AVERAGE SCORES >>" << endl;

 try{

  for(int i=0; i<MAX; i++){

   cout << "GROUP " << i+1 << "의 평균은 ";

   cout << g[i].getAverageScore() << "점입니다." << endl;

  }

 }

 catch(DividedBy0 e){

  cout << "EXCEPTION: " << e.getDividend() << "(을)를 ";

  cout << e.getDivisor() << "(으)로 나눴습니다." << endl;

 }



 return 0;

}
```

```
<< GROUP 1 INPUT >>

학생 수를 입력하세요: 4[엔터]

점수의 합을 입력하세요: 417[엔터]

<< GROUP 2 INPUT >>

학생 수를 입력하세요: 0[엔터]

점수의 합을 입력하세요: 174[엔터]

<< GROUP 3 INPUT >>

학생 수를 입력하세요: 2[엔터]

점수의 합을 입력하세요: 227[엔터]



<< AVERAGE SCORES >>

GROUP 1의 평균은 104.25점입니다.

GROUP 2의 평균은 EXCEPTION: 174(을)를 0(으)로 나눴습니다.

[커서]
```

---

> 예외 처리 - 스택 풀기, 다시 throw 하기

```cpp
#include <iostream>

using namespace std;



class DividedBy0{

public:

 DividedBy0(int p, int q):dividend(p),divisor(q){}

 int getDividend(){ return dividend; }

 int getDivisor(){ return divisor; }

private:

 int dividend, divisor;

};



void printAverageScore(int students, int scores){

 if(students == 0) throw DividedBy0(scores, students);

 cout << "평균은 " << scores/(double)students << "점입니다." << endl;

}



int main(){



 int students, scores;

 cout << "학생 수를 입력하세요: ";

 cin >> students;

 cout << "점수의 합을 입력하세요: ";

 cin >> scores;

 try{

  printAverageScore(students, scores);

 }

 catch(DividedBy0 e){

  cout << "EXCEPTION: " << e.getDividend() << "(을)를 ";

  cout << e.getDivisor() << "(으)로 나눴습니다." << endl;

 }



 return 0;

}
```

throw가 발생할 경우, 스택 상에서 가장 가까운 try 문과 붙어 있는 catch 문에 다가감.
- 스택에서 제일 가깝다라는 것은 함수를 호출할 때마다 스택에 쌓이는 점을 생각

try 문을 찾을 때까지 함수에서 지역 변수, 리턴 어드레스 등의 정보를 pop함.

```cpp
#include <iostream>

using namespace std;



class DividedBy0{

public:

 DividedBy0(int p, int q):dividend(p),divisor(q){}

 int getDividend(){ return dividend; }

 int getDivisor(){ return divisor; }

private:

 int dividend, divisor;

};



double getAverageScore(int students, int scores){

 if(students == 0) throw DividedBy0(scores, students);

 return scores/(double)students;

}



void printAverageScore(int students, int scores){

 cout << "평균은 " << getAverageScore(students, scores) << "점입니다." << endl;

}



int main(){



 int students, scores;

 cout << "학생 수를 입력하세요: ";

 cin >> students;

 cout << "점수의 합을 입력하세요: ";

 cin >> scores;

 try{

  printAverageScore(students, scores);

 }

 catch (DividedBy0 e){

  cout << "EXCEPTION: " << e.getDividend() << "(을)를 ";

  cout << e.getDivisor() << "(으)로 나눴습니다." << endl;

 }



 return 0;

}
```

```
학생 수를 입력하세요: 0[엔터]

점수의 합을 입력하세요: 417[엔터]

EXCEPTION: 417(을)를 0(으)로 나눴습니다.

[커서]
```

이렇게 try 문을 찾을 때까지 스택을 pop하는 것을 **스택 풀기**라고 함.

catch 한 다음에 다시 throw도 가능함.

```cpp
#include <iostream>

using namespace std;



class DividedBy0{

public:

 DividedBy0(int p, int q):dividend(p),divisor(q){}

 int getDividend(){ return dividend; }

 int getDivisor(){ return divisor; }

private:

 int dividend, divisor;

};



double getAverageScore(int students, int scores){

 if(students == 0) throw DividedBy0(scores, students);

 return scores/(double)students;

}



void printAverageScore(int students, int scores){

 try{

  cout << "평균은 " << getAverageScore(students, scores) << "점입니다." << endl;

 }

 catch(DividedBy0 e){

  cout << "EXCEPTION: " << e.getDividend() << "(을)를 ";

  cout << e.getDivisor() << "(으)로 나눴습니다." << endl;

  throw;

 }

}



int main(){



 int students, scores;

 cout << "학생 수를 입력하세요: ";

 cin >> students;

 cout << "점수의 합을 입력하세요: ";

 cin >> scores;

 try{

  printAverageScore(students, scores);

 }

 catch (DividedBy0 e){

  cout << "평균 점수를 구하지 못했습니다." << endl;

 }



 return 0;

}
```

`throw;` 만 쓸 경우 예외 객체는 그대로이므로 자료형도 동일.

```
학생 수를 입력하세요: 0[엔터]

점수의 합을 입력하세요: 417[엔터]

EXCEPTION: 417(을)를 0(으)로 나눴습니다.

평균 점수를 구하지 못했습니다.

[커서]
```

---

> 예외 처리 - exception 헤더 파일

`bad_alloc`
- new 연산자가 heap 영역에서 일정량의 공간을 할당하여 그 주소를 리턴함.
- 그러나 공간이 없거나 할당에 실패하면 프로그램은 bad_alloc이라는 예외를 throw함.

```cpp
#include <iostream>

using namespace std;



int main(){



 try{

  while(1){

   new int[1024];

  }

 }

 catch(bad_alloc){

  cout << "new 연산자의 할당이 실패했습니다." << endl;

 }



 return 0;

}
```

`bad_cast`
- `dynamic_cast`가 실패했을 때
- 다운 캐스팅을 할 경우 null 포인터를 리턴하는데, 이때 예외도 발생시킴.

```cpp
#include <iostream>

using namespace std;



class Parent{ virtual void func(){} };

class Child: public Parent{};



int main(){



 Parent *pP = new Parent();

 Child *pC;

 try{

  pC = dynamic_cast<Child*>(pP);

 }

 catch(bad_cast e){

  cout << "dynamic_cast가 실패했습니다." << endl;

 }



 return 0;

}
```

```
dynamic_cast가 실패했습니다.
```

# C++ 강좌 끝!
